<?xml version="1.0"?>
<robot name="Pendulum">
  <material name="green">
    <color rgba=".3 .6 .4 1"/>
  </material>
  <material name="red">
    <color rgba=".9 .1 0 1"/>
  </material>
  <material name="blue">
    <color rgba="0 0 1 1"/>
  </material>
  <link name="world"/>
  <link name="fixed_base">
    <inertial>
      <origin xyz="0 0 0"/>
      <mass value="1.0"/>
      <inertia ixx="0.01" ixy="0" ixz="0" iyy="0.01" iyz="0" izz="0.01"/>
    </inertial>
  </link>
  <joint name="world_joint" type="fixed">
    <parent link="world"/>
    <child link="fixed_base"/>
    <origin xyz="0 0 1"/>
  </joint>
  <link name="base">
    <inertial>
      <origin rpy="0 0 0" xyz="0 0 .015"/>
      <mass value="1"/>
      <inertia ixx="0.001" ixy="0" ixz="0" iyy="0.001" iyz="0" izz="0.001"/>
    </inertial>
    <visual>
      <origin xyz="0 0 .015"/>
      <geometry>
        <sphere radius=".015"/>
      </geometry>
      <material name="green"/>
    </visual>
  </link>
  <joint name="base_weld" type="fixed">
    <parent link="fixed_base"/>
    <child link="base"/>
    <origin xyz="0 0 0"/>
  </joint>
  <link name="arm">
    <inertial>
      <origin rpy="0 0 0" xyz="0 0 -.5"/>
      <mass value="0.5"/>
      <inertia ixx="0.01" ixy="0" ixz="0" iyy="0.01" iyz="0" izz="0.001"/>
    </inertial>
    <visual>
      <origin rpy="0 0 0" xyz="0 0 -.375"/>
      <geometry>
        <cylinder length=".75" radius=".01"/>
      </geometry>
      <material name="red"/>
    </visual>
    <collision>
      <origin rpy="0 0 0" xyz="0 0 -.375"/>
      <geometry>
        <cylinder length=".75" radius=".01"/>
      </geometry>
    </collision>
  </link>
  <joint name="theta" type="continuous">
    <parent link="base"/>
    <child link="arm"/>
    <axis xyz="0 1 0"/>
    <dynamics damping="0.1"/>
  </joint>
  <link name="arm_com">
    <inertial>
      <origin rpy="0 0 0" xyz="0 0 -0.5"/>
      <mass value="0.5"/>
      <inertia ixx="0.01" ixy="0" ixz="0" iyy="0.01" iyz="0" izz="0.001"/>
    </inertial>
    <visual>
      <origin xyz="0 0 -.5"/>
      <geometry>
        <sphere radius=".025"/>
      </geometry>
      <material name="blue">
        <color rgba="0 0 1 1"/>
      </material>
    </visual>
    <collision>
      <origin xyz="0 0 -.5"/>
      <geometry>
        <sphere radius=".025"/>
      </geometry>
    </collision>
  </link>
  <joint name="arm_weld" type="fixed">
    <parent link="arm"/>
    <child link="arm_com"/>
  </joint>
  <transmission name="elbow_trans" type="SimpleTransmission">
    <actuator name="tau"/>
    <joint name="theta"/>
    <mechanicalReduction>1</mechanicalReduction>
  </transmission>
  <gazebo reference="base">
    <material>Gazebo/Green</material>
  </gazebo>
  <gazebo reference="arm">
    <material>Gazebo/Red</material>
  </gazebo>
  <gazebo reference="arm_com">
    <material>Gazebo/Blue</material>
  </gazebo>
  <gazebo>
    <plugin name="gazebo_ros_state_publisher" filename="libgazebo_ros_joint_state_publisher.so">
      <update_rate>100.0</update_rate>
      <joint_name>theta</joint_name>
    </plugin>
  </gazebo>
  <ros2_control name="GazeboSystem" type="system">
    <hardware>
      <plugin>gazebo_ros2_control/GazeboSystem</plugin>
    </hardware>
    <joint name="theta">
      <command_interface name="effort">
        <param name="min">-1000</param>
        <param name="max">1000</param>
      </command_interface>
      <state_interface name="position"/>
      <state_interface name="velocity"/>
      <state_interface name="effort"/>
    </joint>
  </ros2_control>
  <gazebo>
    <plugin name="gazebo_ros2_control" filename="libgazebo_ros2_control.so">
      <parameters>$(find urdf_tutorial)/config/pendulum_controllers.yaml</parameters>
      <robot_param>robot_description</robot_param>
      <robot_param_node>robot_state_publisher</robot_param_node>
      <robot_sim_type>gazebo_ros2_control/GazeboSystem</robot_sim_type>
    </plugin>
  </gazebo>
  <transmission name="theta_trans">
    <type>transmission_interface/SimpleTransmission</type>
    <joint name="theta">
      <hardwareInterface>hardware_interface/EffortJointInterface</hardwareInterface>
    </joint>
    <actuator name="theta_motor">
      <hardwareInterface>hardware_interface/EffortJointInterface</hardwareInterface>
      <mechanicalReduction>1</mechanicalReduction>
    </actuator>
  </transmission>
</robot>